Workbook
Name mat_eur: Inputs!$B$60
Name mat_pct: Inputs!$B$59
Name rte: Inputs!$B$8

Sheet Checks
A1: Check sheet
A2: MASTER FLAG (publish only if OK) | B2: =IF(COUNTIF(B5:B16,"ERROR")=0,"OK","ERROR") -> OK
A4: check | B4: result | C4: sheet
A5: 1. Round-trip efficiency is plausible (0.80-0.95) | B5: =IF(AND(rte>0.8,rte<0.95),"OK","ERROR") -> OK | C5: Inputs
A6: 2. Monthly net revenue = sum of its lines (every row) | B6: =IF(COUNTIF(Monthly_Actuals!$M$4:$M$79,FALSE)=0,"OK","ERROR") -> OK | C6: Monthly_Actuals
A7: 3. Cost lines are entered as positive amounts (sign convention) | B7: =IF(COUNTIF(Monthly_Actuals!$H$4:$I$79,"<0")=0,"OK","ERROR") -> OK | C7: Monthly_Actuals
A8: 4. Bridge: budget + effects = actual (no unexplained residual) | B8: =IF(ABS(Bridge!E33)<0.01,"OK","ERROR") -> OK | C8: Bridge
A9: 5. Bridge: asset columns cross-foot to the portfolio column | B9: =IF(ABS(SUM(Bridge!B17:D28)-SUM(Bridge!E17:E28))<0.01,"OK","ERROR") -> OK | C9: Bridge
A10: 6. Price series complete on every local day incl. DST days | B10: =IF(COUNTIF(Interval_Count!$D$4:$D$2852,"<>0")=0,"OK","ERROR") -> OK | C10: Interval_Count
A11: 7. Intervals in the price file = intervals implied by the calendar (cross-foot) | B11: =IF(SUM(Interval_Count!$C$4:$C$2852)=SUM(Interval_Count!$B$4:$B$2852),"OK","ERROR") -> OK | C11: Interval_Count
A12: 8. Recon: daily differences cross-foot to total statement - total ledger | B12: =IF(ABS(Recon_Daily!I1099-(Recon_Daily!H1099-Recon_Daily!G1099))<0.01,"OK","ERROR") -> OK | C12: Recon_Daily
A13: 9. Activity keys sum to 100 % for every cost pool | B13: =IF(SUMPRODUCT(--(ABS(Product_PnL!F8:F10-1)<0.0001))=3,"OK","ERROR") -> OK | C13: Product_PnL
A14: 10. Joint costs fully allocated - revenue key | B14: =IF(ABS(Product_PnL!G17-Product_PnL!$B$11)<0.01,"OK","ERROR") -> OK | C14: Product_PnL
A15: 11. Joint costs fully allocated - activity key | B15: =IF(ABS(Product_PnL!H17-Product_PnL!$B$11)<0.01,"OK","ERROR") -> OK | C15: Product_PnL
A16: 12. Product L1 contributions = portfolio net revenue in the window (Monthly_Actuals) | B16: =IF(ABS(Product_PnL!B17-SUMIFS(Monthly_Actuals!$K$4:$K$79,Monthly_Actuals!$A$4:$A$79,">="&DATE(2025,10,1),Monthly_Actuals!$A$4:$A$79,"<="&DATE(2026,9,1)))<1,"OK","ERROR") -> OK | C16: Product_PnL

Sheet README
A1: Flex-optimizer controlling case - Excel deliverable
A3: Purpose: interval reconciliation, variance bridge, rolling-forecast scenarios and product profitability for an
A4: illustrative battery portfolio. Day-ahead prices are real (Energy-Charts / SMARD, CC BY 4.0); assets, contracts,
A5: ledger, exchange statements, schedules, meters, reserve and imbalance prices are synthetic and labelled as such.
A7: Sheets: Inputs (all assumptions, blue cells = editable) | Monthly_Actuals | Bridge (live PVM formulas) |
A8: Interval_Count (DST-aware day structure) | Recon_Daily | Break_Register | Scenarios | Product_PnL (allocation
A9: key switch) | Checks (master flag) | Change_Log.
A11: Rule: do not publish any number while Checks!B2 shows ERROR.
A12: Not in scope: accounting treatment, tax, project finance, margining.

Sheet Inputs
A1: Inputs and assumptions (provenance per row)
A2: Blue cells are inputs. 'illustrative assumption' rows must be replaced with company figures.
A4: parameter | B4: value | C4: unit | D4: source | E4: note
A5: timezone | B5: Europe/Berlin | C5: tz | D5: domain primer | E5: all maths in UTC, local time only for reporting
A6: interval_hours | B6: 0.25 | C6: h | D6: domain primer | E6: 15-minute market time unit (MTU)
A7: da_15min_start_utc | B7: 2025-09-30 22:00 | C7: UTC | D7: observed data | E7: day-ahead moved from hourly to 15-minute products on 1 Oct 2025 (local)
A8: round_trip_efficiency | B8: 0.88 | C8: share | D8: domain primer | E8: Li-ion typically 85-90 %
A9: cell_replacement_value | B9: 90000 | C9: EUR/MWh capacity | D9: illustrative assumption
A10: lifetime_full_cycles | B10: 8000 | C10: cycles | D10: illustrative assumption
A11: degradation_cost | B11: 11.25 | C11: EUR/MWh discharged | D11: domain primer | E11: =replacement value / (lifetime cycles x capacity MWh) -> 0
A12: max_cycles_per_day | B12: 1.5 | C12: cycles/day | D12: domain primer | E12: typical warranty limit, e.g. 1.5
A13: soc_start_fraction | B13: 0.5 | C13: share | D13: illustrative assumption | E13: daily start and minimum end state of charge
A14: availability | B14: 0.97 | C14: share | D14: illustrative assumption | E14: share of time the asset can operate
A15: fee_day_ahead | B15: 0.1 | C15: EUR/MWh traded | D15: illustrative assumption | E15: trading + clearing fee, day-ahead
A16: fee_intraday | B16: 0.25 | C16: EUR/MWh traded | D16: illustrative assumption | E16: continuous intraday carries higher fees
A17: intraday_gap_recovery | B17: 0.3 | C17: share of gap | D17: illustrative assumption | E17: share of (perfect foresight - forecast dispatch) revenue recovered by intraday re-trading
A18: intraday_extra_value_share | B18: 0.2 | C18: share of DA perfect-foresight value | D18: illustrative assumption | E18: additional value from intraday volatility beyond the day-ahead (no intraday data downloaded)
A19: intraday_volume_share | B19: 0.25 | C19: share of DA traded MWh | D19: illustrative assumption | E19: intraday re-trading volume relative to the day-ahead volume
A20: imbalance_noise_sd | B20: 0.012 | C20: share of scheduled MWh | D20: illustrative assumption | E20: random metered deviation around the schedule
A21: reserve_price_2022 | B21: 14 | C21: EUR/MW/h | D21: illustrative assumption | E21: modelled path, not market data
A22: reserve_price_2026 | B22: 4.5 | C22: EUR/MW/h | D22: illustrative assumption | E22: market saturation: capacity prices fall as storage is added
A23: reserve_price_monthly_sd | B23: 0.12 | C23: log-sd | D23: illustrative assumption
A24: portfolio_size_operational | B24: 100 | C24: MW | D24: illustrative assumption | E24: three illustrative operating customer assets
A25: portfolio_size_pre_cod | B25: 20 | C25: MW | D25: illustrative assumption | E25: contracted, COD 2027-03 planned
A26: cod_delay_distribution | B26: {0: 0.35, 3: 0.35, 6: 0.2, 9: 0.1} | C26: months: probability | D26: domain primer | E26: delays are the rule in energy projects -> probability-weight the COD
A27: fee_day_ahead_from_2026_04 | B27: 0.12 | C27: EUR/MWh traded | D27: illustrative assumption | E27: exchange tariff change on 2026-04-01; the rolling forecast still carries the old tariff
A28: c1_share_rate | B28: 0.15 | C28: share of net revenue | D28: illustrative assumption | E28: net base, fixed rate
A29: c2_share_low | B29: 0.12 | C29: share | D29: illustrative assumption | E29: tiered: up to the threshold
A30: c2_share_high | B30: 0.2 | C30: share | D30: illustrative assumption | E30: tiered: above the threshold
A31: c2_tier_threshold | B31: 80000 | C31: EUR/MW/yr | D31: illustrative assumption
A32: c2_customer_floor | B32: 55000 | C32: EUR/MW/yr | D32: illustrative assumption | E32: customer receives at least this per year, optimizer tops up (a put option)
A33: c3_share_rate | B33: 0.2 | C33: share | D33: illustrative assumption
A34: c3_min_monthly_fee | B34: 1500 | C34: EUR/month | D34: illustrative assumption | E34: small, complex customers need a minimum fee (cost to serve)
A35: c4_share_rate | B35: 0.15 | C35: share | D35: illustrative assumption | E35: pre-COD asset, same terms as C1
A36: cost_trading_team | B36: 30000 | C36: EUR/month | D36: illustrative assumption | E36: share of traders + quants
A37: cost_data_it | B37: 12000 | C37: EUR/month | D37: illustrative assumption | E37: cloud, market data, tooling
A38: cost_brp | B38: 4000 | C38: EUR/month | D38: illustrative assumption
A39: direct_da_data | B39: 1000 | C39: EUR/month | D39: illustrative assumption | E39: product-specific data/licences
A40: direct_id_data | B40: 5000 | C40: EUR/month | D40: illustrative assumption | E40: order-book data, API/message fees
A41: direct_res_prequal | B41: 2500 | C41: EUR/month | D41: illustrative assumption | E41: prequalification, testing
...

Sheet Monthly_Actuals
A1: Monthly actuals per asset (Layer 1: asset net trading revenue, EUR)
A3: month | B3: asset_id | C3: mw | D3: dis_mwh | E3: traded_mwh | F3: arb_rev | G3: res_rev | H3: fees | I3: deg | J3: imb_cost | K3: net_rev (formula) | L3: net_rev (python) | M3: match
A4: 45292 | B4: BESS-A | C4: 60 | D4: 2417.8207 | E4: 6456.6803 | F4: 87580.411 | G4: 102485.3 | H4: 839.36844 | I4: 27200.483 | J4: -5138.2604 | K4: =F4+G4-H4-I4-J4 -> 167164.12 | L4: 167164.12 | M4: =ABS(K4-L4)<0.01 -> TRUE
A5: 45323 | B5: BESS-A | C5: 60 | D5: 2931.9638 | E5: 7829.6759 | F5: 84871.6 | G5: 95225.111 | H5: 1017.8579 | I5: 32984.592 | J5: 4820.5113 | K5: =F5+G5-H5-I5-J5 -> 141273.75 | L5: 141273.75 | M5: =ABS(K5-L5)<0.01 -> TRUE
A6: 45352 | B6: BESS-A | C6: 60 | D6: 3660.3068 | E6: 9774.6829 | F6: 167078.33 | G6: 109233.2 | H6: 1270.7088 | I6: 41178.452 | J6: -1351.6019 | K6: =F6+G6-H6-I6-J6 -> 235213.97 | L6: 235213.97 | M6: =ABS(K6-L6)<0.01 -> TRUE
A7: 45383 | B7: BESS-A | C7: 60 | D7: 3611.5063 | E7: 9644.3634 | F7: 276986.41 | G7: 87935.813 | H7: 1253.7672 | I7: 40629.446 | J7: 11316.213 | K7: =F7+G7-H7-I7-J7 -> 311722.79 | L7: 311722.79 | M7: =ABS(K7-L7)<0.01 -> TRUE
A8: 45413 | B8: BESS-A | C8: 60 | D8: 3674.5693 | E8: 9812.7704 | F8: 311612.81 | G8: 80831.326 | H8: 1275.6602 | I8: 41338.905 | J8: -8.199921 | K8: =F8+G8-H8-I8-J8 -> 349837.77 | L8: 349837.77 | M8: =ABS(K8-L8)<0.01 -> TRUE
A9: 45444 | B9: BESS-A | C9: 60 | D9: 3658.5919 | E9: 9770.1033 | F9: 332892.71 | G9: 71437.692 | H9: 1270.1134 | I9: 41159.159 | J9: 35.852029 | K9: =F9+G9-H9-I9-J9 -> 361865.28 | L9: 361865.28 | M9: =ABS(K9-L9)<0.01 -> TRUE
A10: 45474 | B10: BESS-A | C10: 60 | D10: 3737.1493 | E10: 9979.8874 | F10: 349697.29 | G10: 86633.31 | H10: 1297.3854 | I10: 42042.93 | J10: -3068.6054 | K10: =F10+G10-H10-I10-J10 -> 396058.89 | L10: 396058.89 | M10: =ABS(K10-L10)<0.01 -> TRUE
A11: 45505 | B11: BESS-A | C11: 60 | D11: 3621.3273 | E11: 9670.59 | F11: 406912.3 | G11: 90559.775 | H11: 1257.1767 | I11: 40739.932 | J11: 8925.2217 | K11: =F11+G11-H11-I11-J11 -> 446549.75 | L11: 446549.75 | M11: =ABS(K11-L11)<0.01 -> TRUE
A12: 45536 | B12: BESS-A | C12: 60 | D12: 3688.9124 | E12: 9851.0728 | F12: 383878.66 | G12: 80869.574 | H12: 1280.6395 | I12: 41500.264 | J12: 9448.0984 | K12: =F12+G12-H12-I12-J12 -> 412519.23 | L12: 412519.23 | M12: =ABS(K12-L12)<0.01 -> TRUE
A13: 45566 | B13: BESS-A | C13: 60 | D13: 3874.9549 | E13: 10347.891 | F13: 302838.32 | G13: 100535.33 | H13: 1345.2258 | I13: 43593.243 | J13: 4498.2277 | K13: =F13+G13-H13-I13-J13 -> 353936.95 | L13: 353936.95 | M13: =ABS(K13-L13)<0.01 -> TRUE
A14: 45597 | B14: BESS-A | C14: 60 | D14: 3094.9412 | E14: 8264.8998 | F14: 268968.28 | G14: 107415.25 | H14: 1074.437 | I14: 34818.089 | J14: -132.74852 | K14: =F14+G14-H14-I14-J14 -> 340623.76 | L14: 340623.76 | M14: =ABS(K14-L14)<0.01 -> TRUE
A15: 45627 | B15: BESS-A | C15: 60 | D15: 2619.8582 | E15: 6996.2122 | F15: 230213.49 | G15: 112164.97 | H15: 909.50758 | I15: 29473.404 | J15: -3006.8852 | K15: =F15+G15-H15-I15-J15 -> 315002.44 | L15: 315002.44 | M15: =ABS(K15-L15)<0.01 -> TRUE
... A79: 46266 | B79: BESS-C | C79: 10 | D79: 432.86582 | E79: 1155.9485 | F79: 77952.959 | G79: 0 | H79: 168.76848 | I79: 4869.7405 | J79: 2759.7816 | K79: =F79+G79-H79-I79-J79 -> 70154.669 | L79: 70154.669 | M79: =ABS(K79-L79)<0.01 -> TRUE
A80: Total | D80: =SUM(D4:D79) -> 0 | E80: =SUM(E4:E79) -> 0 | F80: =SUM(F4:F79) -> 0 | G80: =SUM(G4:G79) -> 0 | H80: =SUM(H4:H79) -> 0 | I80: =SUM(I4:I79) -> 0 | J80: =SUM(J4:J79) -> 0 | K80: =SUM(K4:K79) -> 0 | L80: =SUM(L4:L79) -> 0

Sheet Bridge
A1: Variance bridge June 2026, budget = Dec-2025 rolling forecast - live formulas
A2: Order of effects: volume (MW online) -> mix (arbitrage vs reserve) -> price; arbitrage price effect is split into cycles -> market spread -> capture rate; costs: volume then rate. Same order every month.
A4: Budget drivers | B4: mw | C4: res_share | D4: q | E4: theo | F4: cap | G4: res_price | H4: traded_per_dis | I4: fee_rate | J4: deg_rate | K4: imb_vol_per_dis | L4: imb_rate | M4: net revenue
A5: BESS-A | B5: 60 | C5: 0.3 | D5: 81.637628 | E5: 82.706341 | F5: 1.0669763 | G5: 4006.5925 | H5: 2.6704545 | I5: 0.13 | J5: 11.25 | K5: 0.092340378 | L5: 36.04631 | M5: =B5*(1-C5)*D5*(E5*F5-H5*I5-J5-K5*L5)+B5*C5*G5 -> 323516.91
A6: BESS-B | B6: 30 | C6: 0.2 | D6: 81.638552 | E6: 82.729175 | F6: 1.0666766 | G6: 4006.5925 | H6: 2.6704545 | I6: 0.13 | J6: 11.25 | K6: 0.092340378 | L6: 36.04631 | M6: =B6*(1-C6)*D6*(E6*F6-H6*I6-J6-K6*L6)+B6*C6*G6 -> 167696.47
A7: BESS-C | B7: 10 | C7: 0 | D7: 41.740678 | E7: 86.196797 | F7: 1.060326 | G7: 4006.5925 | H7: 2.6704545 | I7: 0.13 | J7: 11.25 | K7: 0.092340378 | L7: 36.04631 | M7: =B7*(1-C7)*D7*(E7*F7-H7*I7-J7-K7*L7)+B7*C7*G7 -> 31919.519
A10: Actual drivers | B10: mw | C10: res_share | D10: q | E10: theo | F10: cap | G10: res_price | H10: traded_per_dis | I10: fee_rate | J10: deg_rate | K10: imb_vol_per_dis | L10: imb_rate | M10: net revenue
A11: BESS-A | B11: 60 | C11: 0.3 | D11: 82.290162 | E11: 137.29626 | F11: 1.1078676 | G11: 2795.518 | H11: 2.6704545 | I11: 0.146 | J11: 11.25 | K11: 0.038842902 | L11: 10.340359 | M11: =B11*(1-C11)*D11*(E11*F11-H11*I11-J11-K11*L11)+B11*C11*G11 -> 534408.53
A12: BESS-B | B12: 30 | C12: 0.2 | D12: 82.270162 | E12: 137.59453 | F12: 1.105587 | G12: 2795.518 | H12: 2.6704545 | I12: 0.146 | J12: 11.25 | K12: 0.11365798 | L12: 25.764618 | M12: =B12*(1-C12)*D12*(E12*F12-H12*I12-J12-K12*L12)+B12*C12*G12 -> 288372.23
A13: BESS-C | B13: 10 | C13: 0 | D13: 43.479873 | E13: 144.34373 | F13: 1.100054 | G13: 0 | H13: 2.6704545 | I13: 0.146 | J13: 11.25 | K13: 0.030276703 | L13: 213.89035 | M13: =B13*(1-C13)*D13*(E13*F13-H13*I13-J13-K13*L13)+B13*C13*G13 -> 61163.185
A16: Effect (EUR) | B16: BESS-A | C16: BESS-B | D16: BESS-C | E16: Portfolio | F16: explain?
A17: Volume: MW online (COD timing) | B17: =(B11-B5)*((1-C5)*D5*E5*F5+C5*G5) -> 0 | C17: =(B12-B6)*((1-C6)*D6*E6*F6+C6*G6) -> 0 | D17: =(B13-B7)*((1-C7)*D7*E7*F7+C7*G7) -> 0 | E17: =SUM(B17:D17) -> 0 | F17: =AND(ABS(E17)>=mat_eur,ABS(E17)>=mat_pct*ABS(SUM(M5:M7))) -> 0
A18: Mix: arbitrage vs reserve | B18: =B11*(((1-C11)-(1-C5))*D5*E5*F5+(C11-C5)*G5) -> 0 | C18: =B12*(((1-C12)-(1-C6))*D6*E6*F6+(C12-C6)*G6) -> 0 | D18: =B13*(((1-C13)-(1-C7))*D7*E7*F7+(C13-C7)*G7) -> 0 | E18: =SUM(B18:D18) -> 0 | F18: =AND(ABS(E18)>=mat_eur,ABS(E18)>=mat_pct*ABS(SUM(M5:M7))) -> 0
A19: Cycles: MWh per MW | B19: =B11*(1-C11)*(D11-D5)*E5*F5 -> 2418.5009 | C19: =B12*(1-C12)*(D12-D6)*E6*F6 -> 1337.679 | D19: =B13*(1-C13)*(D13-D7)*E7*F7 -> 1589.5672 | E19: =SUM(B19:D19) -> 0 | F19: =AND(ABS(E19)>=mat_eur,ABS(E19)>=mat_pct*ABS(SUM(M5:M7))) -> 0
A20: Market spread (theoretical) | B20: =B11*(1-C11)*D11*(E11-E5)*F5 -> 201309.57 | C20: =B12*(1-C12)*D12*(E12-E6)*F6 -> 115553.89 | D20: =B13*(1-C13)*D13*(E13-E7)*F7 -> 26807.385 | E20: =SUM(B20:D20) -> 0 | F20: =AND(ABS(E20)>=mat_eur,ABS(E20)>=mat_pct*ABS(SUM(M5:M7))) -> 0
A21: Capture rate (algorithm) | B21: =B11*(1-C11)*D11*E11*(F11-F5) -> 19403.783 | C21: =B12*(1-C12)*D12*E12*(F12-F6) -> 10571.114 | D21: =B13*(1-C13)*D13*E13*(F13-F7) -> 2493.3491 | E21: =SUM(B21:D21) -> 0 | F21: =AND(ABS(E21)>=mat_eur,ABS(E21)>=mat_pct*ABS(SUM(M5:M7))) -> 0
A22: Reserve capacity price | B22: =B11*C11*(G11-G5) -> -21799.342 | C22: =B12*C12*(G12-G6) -> -7266.4473 | D22: =B13*C13*(G13-G7) -> 0 | E22: =SUM(B22:D22) -> 0 | F22: =AND(ABS(E22)>=mat_eur,ABS(E22)>=mat_pct*ABS(SUM(M5:M7))) -> 0
A23: Fees: activity | B23: =-I5*(B11*(1-C11)*D11*H11-B5*(1-C5)*D5*H5) -> -9.5143956 | C23: =-I6*(B12*(1-C12)*D12*H12-B6*(1-C6)*D6*H6) -> -5.2624621 | D23: =-I7*(B13*(1-C13)*D13*H13-B7*(1-C7)*D7*H7) -> -6.0377748 | E23: =SUM(B23:D23) -> 0 | F23: =AND(ABS(E23)>=mat_eur,ABS(E23)>=mat_pct*ABS(SUM(M5:M7))) -> 0
A24: Fees: tariff | B24: =-B11*(1-C11)*D11*H11*(I11-I5) -> -147.67344 | C24: =-B12*(1-C12)*D12*H12*(I12-I6) -> -84.364312 | D24: =-B13*(1-C13)*D13*H13*(I13-I7) -> -18.577764 | E24: =SUM(B24:D24) -> 0 | F24: =AND(ABS(E24)>=mat_eur,ABS(E24)>=mat_pct*ABS(SUM(M5:M7))) -> 0
A25: Degradation: volume | B25: =-J5*(B11*(1-C11)*D11-B5*(1-C5)*D5) -> -308.32248 | C25: =-J6*(B12*(1-C12)*D12-B6*(1-C6)*D6) -> -170.53478 | D25: =-J7*(B13*(1-C13)*D13-B7*(1-C7)*D7) -> -195.65948 | E25: =SUM(B25:D25) -> 0 | F25: =AND(ABS(E25)>=mat_eur,ABS(E25)>=mat_pct*ABS(SUM(M5:M7))) -> 0
A26: Degradation: cost rate | B26: =-B11*(1-C11)*D11*(J11-J5) -> 0 | C26: =-B12*(1-C12)*D12*(J12-J6) -> 3.507388e-12 | D26: =-B13*(1-C13)*D13*(J13-J7) -> 0 | E26: =SUM(B26:D26) -> 0 | F26: =AND(ABS(E26)>=mat_eur,ABS(E26)>=mat_pct*ABS(SUM(M5:M7))) -> 0
A27: Imbalance: volume | B27: =-L5*(B11*(1-C11)*D11*K11-B5*(1-C5)*D5*K5) -> 6573.6411 | C27: =-L6*(B12*(1-C12)*D12*K12-B6*(1-C6)*D6*K6) -> -1567.6905 | D27: =-L7*(B13*(1-C13)*D13*K13-B7*(1-C7)*D7*K7) -> 914.82751 | E27: =SUM(B27:D27) -> 0 | F27: =AND(ABS(E27)>=mat_eur,ABS(E27)>=mat_pct*ABS(SUM(M5:M7))) -> 0
A28: Imbalance: price | B28: =-B11*(1-C11)*D11*K11*(L11-L5) -> 3450.981 | C28: =-B12*(1-C12)*D12*K12*(L12-L6) -> 2307.3746 | D28: =-B13*(1-C13)*D13*K13*(L13-L7) -> -2341.1873 | E28: =SUM(B28:D28) -> 0 | F28: =AND(ABS(E28)>=mat_eur,ABS(E28)>=mat_pct*ABS(SUM(M5:M7))) -> 0
A30: Budget net (portfolio) | E30: =SUM(M5:M7) -> 0
A31: + sum of effects | E31: =SUM(E17:E28) -> 0
A32: Actual net (portfolio) | E32: =SUM(M11:M13) -> 0
A33: Check: budget + effects - actual | E33: =E30+E31-E32 -> 0

Sheet Interval_Count
A1: Intervals per local delivery day: only DST days may differ from 96 (92 in March, 100 in October)
A3: local_date | B3: n_expected | C3: n_found | D3: gap
A4: 43466 | B4: 96 | C4: 96 | D4: =C4-B4 -> 0
A5: 43467 | B5: 96 | C5: 96 | D5: =C5-B5 -> 0
A6: 43468 | B6: 96 | C6: 96 | D6: =C6-B6 -> 0
A7: 43469 | B7: 96 | C7: 96 | D7: =C7-B7 -> 0
A8: 43470 | B8: 96 | C8: 96 | D8: =C8-B8 -> 0
A9: 43471 | B9: 96 | C9: 96 | D9: =C9-B9 -> 0
A10: 43472 | B10: 96 | C10: 96 | D10: =C10-B10 -> 0
A11: 43473 | B11: 96 | C11: 96 | D11: =C11-B11 -> 0
A12: 43474 | B12: 96 | C12: 96 | D12: =C12-B12 -> 0
A13: 43475 | B13: 96 | C13: 96 | D13: =C13-B13 -> 0
A14: 43476 | B14: 96 | C14: 96 | D14: =C14-B14 -> 0
A15: 43477 | B15: 96 | C15: 96 | D15: =C15-B15 -> 0
... A2852: 46314 | B2852: 96 | C2852: 96 | D2852: =C2852-B2852 -> 0

Sheet Recon_Daily
A1: Ledger vs exchange statement per asset and local day (EUR)
A3: asset_id | B3: local_date | C3: ledger_rows | D3: ecc_rows | E3: ledger_mwh | F3: ecc_mwh | G3: ledger_eur | H3: ecc_eur | I3: diff_eur
A4: BESS-A | B4: 2025-10-01 | C4: 28 | D4: 28 | E4: -17.181818 | F4: -17.182 | G4: 21368.409 | H4: 21368.34 | I4: =H4-G4 -> -0.06866402
A5: BESS-A | B5: 2025-10-02 | C5: 28 | D5: 28 | E5: -17.181818 | F5: -17.182 | G5: 12752.974 | H5: 12752.87 | I5: =H5-G5 -> -0.10423352
A6: BESS-A | B6: 2025-10-03 | C6: 28 | D6: 28 | E6: -17.181818 | F6: -17.183 | G6: 11348.192 | H6: 11348.04 | I6: =H6-G6 -> -0.1518251
A7: BESS-A | B7: 2025-10-04 | C7: 28 | D7: 28 | E7: -17.181818 | F7: -17.182 | G7: 239.72521 | H7: 239.73 | I7: =H7-G7 -> 0.0047857
A8: BESS-A | B8: 2025-10-05 | C8: 28 | D8: 28 | E8: -17.181818 | F8: -17.182 | G8: 1470.9147 | H8: 1470.92 | I8: =H8-G8 -> 0.00525895
A9: BESS-A | B9: 2025-10-06 | C9: 29 | D9: 29 | E9: -17.181817 | F9: -17.182 | G9: 7653.8357 | H9: 7653.8 | I9: =H9-G9 -> -0.03567261
A10: BESS-A | B10: 2025-10-07 | C10: 27 | D10: 27 | E10: -17.181818 | F10: -17.18 | G10: 17609.621 | H10: 17609.81 | I10: =H10-G10 -> 0.18933779
A11: BESS-A | B11: 2025-10-08 | C11: 27 | D11: 27 | E11: -17.181818 | F11: -17.181 | G11: 10446.516 | H11: 10446.58 | I11: =H11-G11 -> 0.06433492
A12: BESS-A | B12: 2025-10-09 | C12: 27 | D12: 27 | E12: -17.181819 | F12: -17.18 | G12: 5726.3878 | H12: 5726.58 | I12: =H12-G12 -> 0.19224782
A13: BESS-A | B13: 2025-10-10 | C13: 28 | D13: 28 | E13: -17.181818 | F13: -17.182 | G13: 4860.093 | H13: 4860.04 | I13: =H13-G13 -> -0.05300933
A14: BESS-A | B14: 2025-10-11 | C14: 27 | D14: 27 | E14: -17.181819 | F14: -17.18 | G14: 6078.7009 | H14: 6078.85 | I14: =H14-G14 -> 0.14907982
A15: BESS-A | B15: 2025-10-12 | C15: 27 | D15: 27 | E15: -17.181818 | F15: -17.18 | G15: 2952.5807 | H15: 2952.76 | I15: =H15-G15 -> 0.17926848
... A1098: BESS-C | B1098: 2026-09-30 | C1098: 15 | D1098: 15 | E1098: -2.045455 | F1098: -2.045 | G1098: 2249.575 | H1098: 2249.6 | I1098: =H1098-G1098 -> 0.02503648
A1099: Total | G1099: =SUM(G4:G1098) -> 0 | H1099: =SUM(H4:H1098) -> 0 | I1099: =SUM(I4:I1098) -> 0

Sheet Break_Register
A1: Break register (two-way core + four-way extension) - status column is an input
A3: break_id | B3: scope | C3: asset_id | D3: local_date | E3: type | F3: n_intervals | G3: mwh_diff | H3: eur_impact | I3: severity | J3: owner | K3: root_cause | L3: next_step | M3: age_days | N3: status
A4: R2-BRK-0001 | B4: 2-way | C4: BESS-A | D4: 2026-05-07 | E4: MISSING_IN_ECC | F4: 8 | G4: 84 | H4: 8553.09 | I4: high | J4: exchange ops / data feed | K4: ECC statement incomplete or late | L4: re-request statement | M4: 146 | N4: open
A5: R2-BRK-0002 | B5: 2-way | C5: BESS-A | D5: 2026-01-17 | E5: MISSING_IN_ECC | F5: 8 | G5: -44.526835 | H5: -6884.4383 | I5: high | J5: exchange ops / data feed | K5: ECC statement incomplete or late | L5: re-request statement | M5: 255 | N5: open
A6: R2-BRK-0003 | B6: 2-way | C6: BESS-B | D6: 2025-10-31 | E6: UNIT_X4 | F6: 28 | G6: 29.454728 | H6: -6110.2604 | I6: high | J6: data science export | K6: MW vs MWh confusion (15 min = factor 4) | L6: fix export unit, re-load day | M6: 333 | N6: open
A7: R2-BRK-0004 | B7: 2-way | C7: BESS-C | D7: 2026-09-29 | E7: SIGN_FLIP | F7: 16 | G7: 4.090455 | H7: -3795.5749 | I7: high | J7: exchange ops / data feed | K7: buy / sell convention reversed | L7: map buy/sell columns, re-load day | M7: 1 | N7: open
A8: R2-BRK-0005 | B8: 2-way | C8: BESS-B | D8: 2026-02-06 | E8: UNIT_X4 | F8: 28 | G8: 29.454728 | H8: -2706.7948 | I8: high | J8: data science export | K8: MW vs MWh confusion (15 min = factor 4) | L8: fix export unit, re-load day | M8: 235 | N8: open
A9: R2-BRK-0006 | B9: 2-way | C9: BESS-B | D9: 2025-12-06 | E9: MISSING_IN_LEDGER | F9: 6 | G9: -19.584 | H9: -1293.49 | I9: medium | J9: data science export | K9: trades absent from ledger export | L9: re-run export, check booking cut-off | M9: 297 | N9: open
A10: R2-BRK-0007 | B10: 2-way | C10: BESS-A | D10: 2026-02-13 | E10: DUPLICATE_ECC | F10: 12 | G10: -26.544 | H10: -704.47 | I10: medium | J10: exchange ops / data feed | K10: statement rows delivered twice | L10: de-duplicate on (account, interval) | M10: 228 | N10: open
A11: R2-BRK-0008 | B11: 2-way | C11: BESS-A | D11: 2026-05-14 | E11: MISSING_IN_ECC | F11: 8 | G11: 84 | H11: 503.37 | I11: medium | J11: exchange ops / data feed | K11: ECC statement incomplete or late | L11: re-request statement | M11: 139 | N11: open
A12: R2-BRK-0009 | B12: 2-way | C12: BESS-C | D12: 2026-05-10 | E12: VOLUME_DIFF | F12: 8 | G12: 1.224168 | H12: -421.42385 | I12: medium | J12: trading desk | K12: partial fill / cancellation not reflected in ledger | L12: book executed volume | M12: 143 | N12: open
A13: R2-BRK-0010 | B13: 2-way | C13: BESS-C | D13: 2025-11-24 | E13: VOLUME_DIFF | F13: 8 | G13: 0.085168 | H13: -373.36286 | I13: medium | J13: trading desk | K13: partial fill / cancellation not reflected in ledger | L13: book executed volume | M13: 309 | N13: open
A14: R2-BRK-0011 | B14: 2-way | C14: BESS-B | D14: 2026-07-25 | E14: PRICE_DIFF | F14: 18 | G14: 0.00018 | H14: -345.46192 | I14: medium | J14: exchange / pricing | K14: clearing price corrected after first publication | L14: take final price, true-up | M14: 67 | N14: open
A15: R2-BRK-0012 | B15: 2-way | C15: BESS-C | D15: 2026-09-05 | E15: VOLUME_DIFF | F15: 8 | G15: -1.480581 | H15: -307.92394 | I15: medium | J15: trading desk | K15: partial fill / cancellation not reflected in ledger | L15: book executed volume | M15: 25 | N15: open
... A134: R4-BRK-0107 | B134: 4-way | C134: BESS-C | D134: 2025-11-02 | E134: ASSET_OUTAGE | F134: 2 | G134: -0.166251 | H134: -0.44005622 | I134: low | J134: asset / customer | K134: unplanned outage: meter below schedule | L134: availability KPI; imbalance to asset side | M134: 331 | N134: open

Sheet Scenarios
A1: Rolling forecast accuracy, scenarios, tornado and Monte Carlo (12 months forward)
A3: Backtest: accuracy by horizon (portfolio, monthly)
A4: h | B4: n | C4: MAPE % | D4: bias % (forecast-actual)
A5: 1 | B5: 21 | C5: 32.7 | D5: -10.2
A6: 2 | B6: 20 | C6: 34.9 | D6: -11.2
A7: 3 | B7: 19 | C7: 37.1 | D7: -12.4
A8: 4 | B8: 18 | C8: 38.7 | D8: -12.7
A9: 5 | B9: 17 | C9: 39.6 | D9: -12.4
A10: 6 | B10: 16 | C10: 40.4 | D10: -11.9
A11: 7 | B11: 15 | C11: 40.6 | D11: -10.8
A12: 8 | B12: 14 | C12: 41.1 | D12: -11
A13: 9 | B13: 13 | C13: 41.7 | D13: -11
A14: 10 | B14: 12 | C14: 41.8 | D14: -10.6
A15: 11 | B15: 11 | C15: 43.8 | D15: -12.5
A16: 12 | B16: 10 | C16: 44.5 | D16: -15.6
A19: Scenario sets (EUR, 12 months)
A20: scenario | B20: layer1_net | C20: company_revenue | D20: floor_topup | E20: cost_to_serve | F20: direct_costs | G20: joint_costs | H20: company_ebitda
A21: Stress | B21: 2947749.4 | C21: -393545.2 | D21: 816687.1 | E21: 126000 | F21: 102000 | G21: 552000 | H21: -1173545.2
A22: Downside | B22: 6028897.9 | C22: 866711.03 | D22: 0 | E22: 128500 | F22: 102000 | G22: 552000 | H22: 84211.035
A23: Base | B23: 7952877.6 | C23: 1145638.8 | D23: 0 | E23: 136125 | F23: 102000 | G23: 552000 | H23: 355513.77
A24: Upside | B24: 10513152 | C24: 1568435.9 | D24: 0 | E24: 143500 | F24: 102000 | G24: 552000 | H24: 770935.88
A27: Tornado - Layer 1 net trading revenue (change vs base, EUR)
A28: driver | B28: low | C28: high | D28: range
A29: Market spread level (P10 / P90) | B29: -3883320.3 | C29: 8724146.5 | D29: 12607467
A30: Cycles per MW (-10 / +10 %) | B30: -696706.78 | C30: 696706.78 | D30: 1393413.6
A31: COD of pre-COD asset (+9 m / on plan) | B31: -573749.28 | C31: 392717.16 | D31: 966466.44
A32: Capture rate (-5 / +5 pp) | B32: -370329.6 | C32: 370329.6 | D32: 740659.21
A33: Reserve capacity price (-35 / +15 %) | B33: -345033.44 | C33: 147871.47 | D33: 492904.91
A34: Imbalance price (+30 / -30 %) | B34: -59253.482 | C34: 59253.482 | D34: 118506.96
A35: Exchange fees (+25 / -25 %) | B35: -6837.8096 | C35: 6837.8096 | D35: 13675.619
A36: Revenue share rate (-3 / +3 pp) | B36: 0 | C36: 0 | D36: 0
A39: Tornado - company EBITDA (change vs base, EUR)
A40: driver | B40: low | C40: high | D40: range
A41: Market spread level (P10 / P90) | B41: -1162756.7 | C41: 1475391 | D41: 2638147.7
A42: Revenue share rate (-3 / +3 pp) | B42: -238586.33 | C42: 238586.33 | D42: 477172.66
A43: Cycles per MW (-10 / +10 %) | B43: -100536.68 | C43: 117825.67 | D43: 218362.35
A44: COD of pre-COD asset (+9 m / on plan) | B44: -75937.392 | C44: 51532.574 | D44: 127469.97
A45: Capture rate (-5 / +5 pp) | B45: -53494.709 | C45: 62649.372 | D45: 116144.08
A46: Reserve capacity price (-35 / +15 %) | B46: -49414.809 | C46: 23907.307 | D46: 73322.116
A47: Imbalance price (+30 / -30 %) | B47: -8610.1251 | C47: 10019.833 | D47: 18629.958
...

Sheet Product_PnL
A1: Product profitability, Oct-2025 to Sep-2026 (company view, EUR) - change the key in B3
A3: Allocation key | B3: Activity
A4: Months in window | B4: 12
A7: Joint cost pool (EUR / month) | B7: monthly cost | C7: key: Day-ahead | D7: key: Intraday | E7: key: Reserve capacity | F7: key sum
A8: Trading team | B8: 30000 | C8: 0.18 | D8: 0.67 | E8: 0.15 | F8: =SUM(C8:E8) -> 1
A9: Data & IT | B9: 12000 | C9: 0.2 | D9: 0.55 | E9: 0.25 | F9: =SUM(C9:E9) -> 1
A10: Balance group (BRP) | B10: 4000 | C10: 0.35 | D10: 0.55 | E10: 0.1 | F10: =SUM(C10:E10) -> 1
A11: Joint costs in window | B11: =SUM(B8:B10)*$B$4 -> 0
A13: product | B13: L1 contribution | C13: company revenue | D13: direct costs / month | E13: direct costs | F13: CM1 | G13: joint (revenue key) | H13: joint (activity key) | I13: joint (selected) | J13: net contribution
A14: Day-ahead | B14: 5114042 | C14: 738761.59 | D14: 1000 | E14: =D14*$B$4 -> 0 | F14: =C14-E14 -> 0 | G14: =MAX(C14,0)/SUMPRODUCT((C$14:C$16>0)*C$14:C$16)*$B$11 -> 0 | H14: =SUMPRODUCT($B$8:$B$10,C$8:C$10)*$B$4 -> 0 | I14: =IF($B$3="Revenue",G14,H14) -> 0 | J14: =F14-I14 -> 0
A15: Intraday | B15: 1474047.1 | C15: 213345.64 | D15: 5000 | E15: =D15*$B$4 -> 0 | F15: =C15-E15 -> 0 | G15: =MAX(C15,0)/SUMPRODUCT((C$14:C$16>0)*C$14:C$16)*$B$11 -> 0 | H15: =SUMPRODUCT($B$8:$B$10,D$8:D$10)*$B$4 -> 0 | I15: =IF($B$3="Revenue",G15,H15) -> 0 | J15: =F15-I15 -> 0
A16: Reserve capacity | B16: 993369.88 | C16: 142232.19 | D16: 2500 | E16: =D16*$B$4 -> 0 | F16: =C16-E16 -> 0 | G16: =MAX(C16,0)/SUMPRODUCT((C$14:C$16>0)*C$14:C$16)*$B$11 -> 0 | H16: =SUMPRODUCT($B$8:$B$10,E$8:E$10)*$B$4 -> 0 | I16: =IF($B$3="Revenue",G16,H16) -> 0 | J16: =F16-I16 -> 0
A17: Total | B17: =SUM(B14:B16) -> 0 | C17: =SUM(C14:C16) -> 0 | E17: =SUM(E14:E16) -> 0 | F17: =SUM(F14:F16) -> 0 | G17: =SUM(G14:G16) -> 0 | H17: =SUM(H14:H16) -> 0 | I17: =SUM(I14:I16) -> 0 | J17: =SUM(J14:J16) -> 0
A20: customer | B20: asset_id | C20: type | D20: MW | E20: contract | F20: company_revenue | G20: of_which_floor_topup | H20: cost_to_serve | I20: after cost to serve | J20: cost to serve / MW
A21: C1 | B21: BESS-A | C21: stand-alone | D21: 60 | E21: net_fixed | F21: 690251.4 | G21: 0 | H21: 29979.466 | I21: =F21-H21 -> 0 | J21: =H21/D21 -> 0
A22: C2 | B22: BESS-B | C22: co-located | D22: 30 | E22: tiered_floor | F22: 304724.36 | G22: 0 | H22: 59958.932 | I22: =F22-H22 -> 0 | J22: =H22/D22 -> 0
A23: C3 | B23: BESS-C | C23: stand-alone | D23: 10 | E23: fixed_min_fee | F23: 99363.663 | G23: 0 | H23: 35975.359 | I23: =F23-H23 -> 0 | J23: =H23/D23 -> 0

Sheet Change_Log
A1: Change log
A3: date | B3: version | C3: change
A4: 46315 | B4: 1.0 | C4: First version: data audit, reconciliation, bridge, scenarios, product P&L.
